Workbook

Sheet Clashbook
A1: Cashbook - Daily Income & Expanses
E3: 0 | I3: Daily revenue report
C4: Total Income | E4: =SUM(E9:E508) -> 7000000 | F4: check | G4: =IF(COUNT(A9:A508)=0,0,ROUND(E6-INDEX(G9:G508,MATCH(9.99E+307,G9:G508)),2)) -> 0 | I4: Select Date | J4: 46113
C5: Total Expenses | E5: =SUM(F9:F508) -> 5577000 | G5: =IF(G4=0,"✔ Check pass","✘ Check again") -> ✔ Check pass | I5: day's income | J5: =SUMIFS(E9:E508,A9:A508,J4) -> 700000
C6: Closing Balance | E6: =E3+E4-E5 -> 1423000 | F6: No. of item | G6: =COUNT(A9:A508) -> 105 | I6: day's expenses | J6: =SUMIFS(F9:F508,A9:A508,J4) -> 130000
I7: Net amount | J7: =J5-J6 -> 570000
A8: Date | B8: Day | C8: List | D8: Category | E8: Income | F8: Expenses | G8: Balance
A9: 46113 | B9: =IF(A9="","",TEXT(A9,"dddd")) -> Wednesday | C9: Weekly allowance | D9: Money | E9: 700000 | G9: =IF(A9="","",$E$3+SUM($E$9:E9)-SUM($F$9:F9)) -> 700000
A10: 46113 | B10: =IF(A10="","",TEXT(A10,"dddd")) -> Wednesday | C10: Meals | F10: 50000 | G10: =IF(A10="","",$E$3+SUM($E$9:E10)-SUM($F$9:F10)) -> 650000
A11: 46113 | B11: =IF(A11="","",TEXT(A11,"dddd")) -> Wednesday | C11: Coffee | F11: 30000 | G11: =IF(A11="","",$E$3+SUM($E$9:E11)-SUM($F$9:F11)) -> 620000
A12: 46113 | B12: =IF(A12="","",TEXT(A12,"dddd")) -> Wednesday | C12: Meals | F12: 50000 | G12: =IF(A12="","",$E$3+SUM($E$9:E12)-SUM($F$9:F12)) -> 570000
A13: 46114 | B13: =IF(A13="","",TEXT(A13,"dddd")) -> Thursday | C13: Meals | F13: 50000 | G13: =IF(A13="","",$E$3+SUM($E$9:E13)-SUM($F$9:F13)) -> 520000
A14: 46114 | B14: =IF(A14="","",TEXT(A14,"dddd")) -> Thursday | C14: Snack | F14: 20000 | G14: =IF(A14="","",$E$3+SUM($E$9:E14)-SUM($F$9:F14)) -> 500000
A15: 46114 | B15: =IF(A15="","",TEXT(A15,"dddd")) -> Thursday | C15: Snack | F15: 15000 | G15: =IF(A15="","",$E$3+SUM($E$9:E15)-SUM($F$9:F15)) -> 485000
A16: 46114 | B16: =IF(A16="","",TEXT(A16,"dddd")) -> Thursday | C16: Meals | F16: 50000 | G16: =IF(A16="","",$E$3+SUM($E$9:E16)-SUM($F$9:F16)) -> 435000
A17: 46115 | B17: =IF(A17="","",TEXT(A17,"dddd")) -> Friday | C17: Water | F17: 10000 | G17: =IF(A17="","",$E$3+SUM($E$9:E17)-SUM($F$9:F17)) -> 425000
A18: 46115 | B18: =IF(A18="","",TEXT(A18,"dddd")) -> Friday | C18: Coffee | F18: 30000 | G18: =IF(A18="","",$E$3+SUM($E$9:E18)-SUM($F$9:F18)) -> 395000
A19: 46115 | B19: =IF(A19="","",TEXT(A19,"dddd")) -> Friday | C19: Meals | F19: 50000 | G19: =IF(A19="","",$E$3+SUM($E$9:E19)-SUM($F$9:F19)) -> 345000
A20: 46116 | B20: =IF(A20="","",TEXT(A20,"dddd")) -> Saturday | C20: Meals | F20: 50000 | G20: =IF(A20="","",$E$3+SUM($E$9:E20)-SUM($F$9:F20)) -> 295000
A21: 46116 | B21: =IF(A21="","",TEXT(A21,"dddd")) -> Saturday | C21: Meals | F21: 50000 | G21: =IF(A21="","",$E$3+SUM($E$9:E21)-SUM($F$9:F21)) -> 245000
... A24: 46118 | B24: =IF(A24="","",TEXT(A24,"dddd")) -> Monday | C24: Meals | F24: 50000 | G24: =IF(A24="","",$E$3+SUM($E$9:E24)-SUM($F$9:F24)) -> 115000
A25: 46120 | B25: =IF(A25="","",TEXT(A25,"dddd")) -> Wednesday | C25: Weekly allowance | D25: Money | E25: 700000 | G25: =IF(A25="","",$E$3+SUM($E$9:E25)-SUM($F$9:F25)) -> 815000
A26: 46120 | B26: =IF(A26="","",TEXT(A26,"dddd")) -> Wednesday | C26: Meals | F26: 50000 | G26: =IF(A26="","",$E$3+SUM($E$9:E26)-SUM($F$9:F26)) -> 765000
A27: 46121 | B27: =IF(A27="","",TEXT(A27,"dddd")) -> Thursday | C27: Coffee | F27: 30000 | G27: =IF(A27="","",$E$3+SUM($E$9:E27)-SUM($F$9:F27)) -> 735000
A28: 46121 | B28: =IF(A28="","",TEXT(A28,"dddd")) -> Thursday | C28: Meals | F28: 50000 | G28: =IF(A28="","",$E$3+SUM($E$9:E28)-SUM($F$9:F28)) -> 685000
A29: 46122 | B29: =IF(A29="","",TEXT(A29,"dddd")) -> Friday | C29: Meals | F29: 50000 | G29: =IF(A29="","",$E$3+SUM($E$9:E29)-SUM($F$9:F29)) -> 635000
A30: 46123 | B30: =IF(A30="","",TEXT(A30,"dddd")) -> Saturday | C30: Meals | F30: 50000 | G30: =IF(A30="","",$E$3+SUM($E$9:E30)-SUM($F$9:F30)) -> 585000
A31: 46124 | B31: =IF(A31="","",TEXT(A31,"dddd")) -> Sunday | C31: Meals | F31: 50000 | G31: =IF(A31="","",$E$3+SUM($E$9:E31)-SUM($F$9:F31)) -> 535000
A32: 46125 | B32: =IF(A32="","",TEXT(A32,"dddd")) -> Monday | C32: BBQ | F32: 150000 | G32: =IF(A32="","",$E$3+SUM($E$9:E32)-SUM($F$9:F32)) -> 385000
A33: 46126 | B33: =IF(A33="","",TEXT(A33,"dddd")) -> Tuesday | C33: Coffee | F33: 50000 | G33: =IF(A33="","",$E$3+SUM($E$9:E33)-SUM($F$9:F33)) -> 335000
A34: 46127 | B34: =IF(A34="","",TEXT(A34,"dddd")) -> Wednesday | C34: Weekly allowance | D34: Money | E34: 700000 | G34: =IF(A34="","",$E$3+SUM($E$9:E34)-SUM($F$9:F34)) -> 1035000
A35: 46127 | B35: =IF(A35="","",TEXT(A35,"dddd")) -> Wednesday | C35: Meals | F35: 50000 | G35: =IF(A35="","",$E$3+SUM($E$9:E35)-SUM($F$9:F35)) -> 985000
A36: 46127 | B36: =IF(A36="","",TEXT(A36,"dddd")) -> Wednesday | C36: Meals | F36: 50000 | G36: =IF(A36="","",$E$3+SUM($E$9:E36)-SUM($F$9:F36)) -> 935000
A37: 46128 | B37: =IF(A37="","",TEXT(A37,"dddd")) -> Thursday | C37: Coffee | F37: 30000 | G37: =IF(A37="","",$E$3+SUM($E$9:E37)-SUM($F$9:F37)) -> 905000
A38: 46129 | B38: =IF(A38="","",TEXT(A38,"dddd")) -> Friday | C38: Meals | F38: 50000 | G38: =IF(A38="","",$E$3+SUM($E$9:E38)-SUM($F$9:F38)) -> 855000
A39: 46130 | B39: =IF(A39="","",TEXT(A39,"dddd")) -> Saturday | C39: Meals | F39: 50000 | G39: =IF(A39="","",$E$3+SUM($E$9:E39)-SUM($F$9:F39)) -> 805000
A40: 46133 | B40: =IF(A40="","",TEXT(A40,"dddd")) -> Tuesday | C40: BBQ | F40: 150000 | G40: =IF(A40="","",$E$3+SUM($E$9:E40)-SUM($F$9:F40)) -> 655000
A41: 46134 | B41: =IF(A41="","",TEXT(A41,"dddd")) -> Wednesday | C41: Weekly allowance | D41: Money | E41: 700000 | G41: =IF(A41="","",$E$3+SUM($E$9:E41)-SUM($F$9:F41)) -> 1355000
A42: 46134 | B42: =IF(A42="","",TEXT(A42,"dddd")) -> Wednesday | C42: Meals | F42: 70000 | G42: =IF(A42="","",$E$3+SUM($E$9:E42)-SUM($F$9:F42)) -> 1285000
A43: 46134 | B43: =IF(A43="","",TEXT(A43,"dddd")) -> Wednesday | C43: Coffee | F43: 30000 | G43: =IF(A43="","",$E$3+SUM($E$9:E43)-SUM($F$9:F43)) -> 1255000
...

Sheet Monthly
A3: ປີ (ຄ.ສ.) | B3: 2026 | D3: ເລືອກວັນທີ່ | E3: 46113
A4: ເດືອນ (1-12) | B4: 4 | D4: ລາຍຮັບມື້ນັ້ນ | E4: =SUMIFS(Clashbook!$E$9:$E$508,Clashbook!$A$9:$A$508,E3) -> 700000
A5: ມື້ແລກຂອງເດືອນ | B5: =DATE(B3,B4,1) -> 46113 | D5: ລາຍຈ່າຍມື້ນັ້ນ | E5: =SUMIFS(Clashbook!$F$9:$F$508,Clashbook!$A$9:$A$508,E3) -> 130000
A6: ມື້ສຸດທ້າຍຂອງເດືອນ | B6: =EOMONTH(B5,0) -> 46142 | D6: ຈຳນວນລາຍການມື້ນັ້ນ | E6: =COUNTIFS(Clashbook!$A$9:$A$508,E3) -> 4
A7: ຈຳນວນມື້ | B7: =DAY(B6) -> 30 | D7: ຈ່າຍສະສົມຕົ້ນເດືອນຮອດມື້ນັ້ນ | E7: =SUMIFS(Clashbook!$F$9:$F$508,Clashbook!$A$9:$A$508,">="&B5,Clashbook!$A$9:$A$508,"<="&E3) -> 130000
A9: ວັນທີ່ | B9: ລາຍຮັບ | C9: ລາຍຈ່າຍ | D9: ສຸດທິ | E9: ຈຳນວນລາຍການ
A10: =B5 -> 46113 | B10: =IF(A10="","",SUMIFS(Clashbook!$E$9:$E$508,Clashbook!$A$9:$A$508,A10)) -> 700000 | C10: =IF(A10="","",SUMIFS(Clashbook!$F$9:$F$508,Clashbook!$A$9:$A$508,A10)) -> 130000 | D10: =IF(A10="","",B10-C10) -> 570000 | E10: =IF(A10="","",COUNTIFS(Clashbook!$A$9:$A$508,A10)) -> 4
A11: =IF(A10="","",IF(A10+1>$B$6,"",A10+1)) -> 46114 | B11: =IF(A11="","",SUMIFS(Clashbook!$E$9:$E$508,Clashbook!$A$9:$A$508,A11)) -> 0 | C11: =IF(A11="","",SUMIFS(Clashbook!$F$9:$F$508,Clashbook!$A$9:$A$508,A11)) -> 135000 | D11: =IF(A11="","",B11-C11) -> -135000 | E11: =IF(A11="","",COUNTIFS(Clashbook!$A$9:$A$508,A11)) -> 4
A12: =IF(A11="","",IF(A11+1>$B$6,"",A11+1)) -> 46115 | B12: =IF(A12="","",SUMIFS(Clashbook!$E$9:$E$508,Clashbook!$A$9:$A$508,A12)) -> 0 | C12: =IF(A12="","",SUMIFS(Clashbook!$F$9:$F$508,Clashbook!$A$9:$A$508,A12)) -> 90000 | D12: =IF(A12="","",B12-C12) -> -90000 | E12: =IF(A12="","",COUNTIFS(Clashbook!$A$9:$A$508,A12)) -> 3
A13: =IF(A12="","",IF(A12+1>$B$6,"",A12+1)) -> 46116 | B13: =IF(A13="","",SUMIFS(Clashbook!$E$9:$E$508,Clashbook!$A$9:$A$508,A13)) -> 0 | C13: =IF(A13="","",SUMIFS(Clashbook!$F$9:$F$508,Clashbook!$A$9:$A$508,A13)) -> 100000 | D13: =IF(A13="","",B13-C13) -> -100000 | E13: =IF(A13="","",COUNTIFS(Clashbook!$A$9:$A$508,A13)) -> 2
A14: =IF(A13="","",IF(A13+1>$B$6,"",A13+1)) -> 46117 | B14: =IF(A14="","",SUMIFS(Clashbook!$E$9:$E$508,Clashbook!$A$9:$A$508,A14)) -> 0 | C14: =IF(A14="","",SUMIFS(Clashbook!$F$9:$F$508,Clashbook!$A$9:$A$508,A14)) -> 80000 | D14: =IF(A14="","",B14-C14) -> -80000 | E14: =IF(A14="","",COUNTIFS(Clashbook!$A$9:$A$508,A14)) -> 2
A15: =IF(A14="","",IF(A14+1>$B$6,"",A14+1)) -> 46118 | B15: =IF(A15="","",SUMIFS(Clashbook!$E$9:$E$508,Clashbook!$A$9:$A$508,A15)) -> 0 | C15: =IF(A15="","",SUMIFS(Clashbook!$F$9:$F$508,Clashbook!$A$9:$A$508,A15)) -> 50000 | D15: =IF(A15="","",B15-C15) -> -50000 | E15: =IF(A15="","",COUNTIFS(Clashbook!$A$9:$A$508,A15)) -> 1
A16: =IF(A15="","",IF(A15+1>$B$6,"",A15+1)) -> 46119 | B16: =IF(A16="","",SUMIFS(Clashbook!$E$9:$E$508,Clashbook!$A$9:$A$508,A16)) -> 0 | C16: =IF(A16="","",SUMIFS(Clashbook!$F$9:$F$508,Clashbook!$A$9:$A$508,A16)) -> 0 | D16: =IF(A16="","",B16-C16) -> 0 | E16: =IF(A16="","",COUNTIFS(Clashbook!$A$9:$A$508,A16)) -> 0
A17: =IF(A16="","",IF(A16+1>$B$6,"",A16+1)) -> 46120 | B17: =IF(A17="","",SUMIFS(Clashbook!$E$9:$E$508,Clashbook!$A$9:$A$508,A17)) -> 700000 | C17: =IF(A17="","",SUMIFS(Clashbook!$F$9:$F$508,Clashbook!$A$9:$A$508,A17)) -> 50000 | D17: =IF(A17="","",B17-C17) -> 650000 | E17: =IF(A17="","",COUNTIFS(Clashbook!$A$9:$A$508,A17)) -> 2
A18: =IF(A17="","",IF(A17+1>$B$6,"",A17+1)) -> 46121 | B18: =IF(A18="","",SUMIFS(Clashbook!$E$9:$E$508,Clashbook!$A$9:$A$508,A18)) -> 0 | C18: =IF(A18="","",SUMIFS(Clashbook!$F$9:$F$508,Clashbook!$A$9:$A$508,A18)) -> 80000 | D18: =IF(A18="","",B18-C18) -> -80000 | E18: =IF(A18="","",COUNTIFS(Clashbook!$A$9:$A$508,A18)) -> 2
A19: =IF(A18="","",IF(A18+1>$B$6,"",A18+1)) -> 46122 | B19: =IF(A19="","",SUMIFS(Clashbook!$E$9:$E$508,Clashbook!$A$9:$A$508,A19)) -> 0 | C19: =IF(A19="","",SUMIFS(Clashbook!$F$9:$F$508,Clashbook!$A$9:$A$508,A19)) -> 50000 | D19: =IF(A19="","",B19-C19) -> -50000 | E19: =IF(A19="","",COUNTIFS(Clashbook!$A$9:$A$508,A19)) -> 1
A20: =IF(A19="","",IF(A19+1>$B$6,"",A19+1)) -> 46123 | B20: =IF(A20="","",SUMIFS(Clashbook!$E$9:$E$508,Clashbook!$A$9:$A$508,A20)) -> 0 | C20: =IF(A20="","",SUMIFS(Clashbook!$F$9:$F$508,Clashbook!$A$9:$A$508,A20)) -> 50000 | D20: =IF(A20="","",B20-C20) -> -50000 | E20: =IF(A20="","",COUNTIFS(Clashbook!$A$9:$A$508,A20)) -> 1
A21: =IF(A20="","",IF(A20+1>$B$6,"",A20+1)) -> 46124 | B21: =IF(A21="","",SUMIFS(Clashbook!$E$9:$E$508,Clashbook!$A$9:$A$508,A21)) -> 0 | C21: =IF(A21="","",SUMIFS(Clashbook!$F$9:$F$508,Clashbook!$A$9:$A$508,A21)) -> 50000 | D21: =IF(A21="","",B21-C21) -> -50000 | E21: =IF(A21="","",COUNTIFS(Clashbook!$A$9:$A$508,A21)) -> 1
A22: =IF(A21="","",IF(A21+1>$B$6,"",A21+1)) -> 46125 | B22: =IF(A22="","",SUMIFS(Clashbook!$E$9:$E$508,Clashbook!$A$9:$A$508,A22)) -> 0 | C22: =IF(A22="","",SUMIFS(Clashbook!$F$9:$F$508,Clashbook!$A$9:$A$508,A22)) -> 150000 | D22: =IF(A22="","",B22-C22) -> -150000 | E22: =IF(A22="","",COUNTIFS(Clashbook!$A$9:$A$508,A22)) -> 1
... A40: =IF(A39="","",IF(A39+1>$B$6,"",A39+1)) | B40: =IF(A40="","",SUMIFS(Clashbook!$E$9:$E$508,Clashbook!$A$9:$A$508,A40)) | C40: =IF(A40="","",SUMIFS(Clashbook!$F$9:$F$508,Clashbook!$A$9:$A$508,A40)) | D40: =IF(A40="","",B40-C40) | E40: =IF(A40="","",COUNTIFS(Clashbook!$A$9:$A$508,A40))
A41: ລວມທັງເດືອນ | B41: =SUM(B10:B40) -> 3500000 | C41: =SUM(C10:C40) -> 2182000 | D41: =SUM(D10:D40) -> 1318000 | E41: =SUM(E10:E40) -> 47
A43: ວັນທີ່ມີລາຍການ | B43: =COUNTIF(E10:E40,">0") -> 26
A44: ລາຍຈ່າຍສະເລ່ຍຕໍ່ມື້ | B44: =IFERROR(C41/B7,0) -> 72733.333
A45: Check (ຕ້ອງ = 0) | B45: =ROUND(C41-SUMIFS(Clashbook!$F$9:$F$508,Clashbook!$A$9:$A$508,">="&B5,Clashbook!$A$9:$A$508,"<="&B6),2) -> 0

Sheet Tax
A5: ອັດຕາ Vat | B5: 0.07
A6: ອັດຕາຫັກຂະນະທີ່ຈ່າຍ | B6: 0.03
A9: ລາຄາສິນຄ້າ (ກ່ອນ Vat) | B9: 100000
A10: Vat | B10: =ROUND(B9*$B$5,2) -> 7000
A11: ຍອດລວມທີ່ລູກຄ້າຈ່າຍ | B11: =B9+B10 -> 107000
A14: ລາຄາປ້າຍ (ລວມ Vat ແລ້ວ) | B14: 100000
A15: ລາຄາກ່ອນ Vat | B15: =ROUND(B14/(1+$B$5),2) -> 93457.94
A16: VAT | B16: =B14-B15 -> 6542.06
A20: ຄ່າບໍລິການ (ກ່ອນ Vat) | B20: 100000
A21: ບວກ Vat | B21: =ROUND(B20*$B$5,2) -> 7000
A22: ຍອດຕາມໃບກຳກັບພາສີ | B22: =B20+B21 -> 107000
A23: ຫັກຂະນະທີ່ຈ່າຍ | B23: =ROUND(B20*$B$6,2) -> 3000
A24: ຍອດໂອນຈ່າຍຈິງ | B24: =B22-B23 -> 104000

Sheet VAT Report
A4: Date | B4: Doc No. | C4: List | D4: Type | E4: Amount (ກ່ອນ VAT) | F4: VAT | G4: Total
A5: 46113 | B5: INV-001 | C5: ຂາຍສິນຄ້າໃຫ້ຮ້ານ A | D5: Sales | E5: 5000000 | F5: =IF(E5="","",ROUND(E5*Tax!$B$5,2)) -> 350000 | G5: =IF(E5="","",E5+F5) -> 5350000 | I5: ຍອດຂາຍ | J5: =SUMIFS($E$5:$E$104,$D$5:$D$104,"Sales") -> 20000000
A6: 46115 | B6: PO-001 | C6: ຊື້ວັດຖຸດິບ | D6: Purchase | E6: 2000000 | F6: =IF(E6="","",ROUND(E6*Tax!$B$5,2)) -> 140000 | G6: =IF(E6="","",E6+F6) -> 2140000 | I6: ພາສີຂາຍ | J6: =SUMIFS($F$5:$F$104,$D$5:$D$104,"Sales") -> 1400000
A7: 46120 | B7: INV-002 | C7: ຂາຍສິນຄ້າໃຫ້ຮ້ານ B | D7: Sales | E7: 3000000 | F7: =IF(E7="","",ROUND(E7*Tax!$B$5,2)) -> 210000 | G7: =IF(E7="","",E7+F7) -> 3210000 | I7: ຍອດຊື້ | J7: =SUMIFS($E$5:$E$104,$D$5:$D$104,"Purchase") -> 10000000
A8: 46124 | B8: PO-002 | C8: ຊື້ສິນຄ້າເຂົ້າຮ້ານ | D8: Purchase | E8: 15000000 | F8: =IF(E8="","",ROUND(E8*Tax!$B$5,2)) -> 1050000 | G8: =IF(E8="","",E8+F8) -> 16050000 | I8: ພາສີຊື້ | J8: =SUMIFS($F$5:$F$104,$D$5:$D$104,"Purchase") -> 700000
A9: 46132 | B9: INV-003 | C9: ຂາຍສິນຄ້າໃຫ້ຮ້ານ B | D9: Sales | E9: 12000000 | F9: =IF(E9="","",ROUND(E9*Tax!$B$5,2)) -> 840000 | G9: =IF(E9="","",E9+F9) -> 12840000 | I9: ພາສີທີ່ຕ້ອງຊຳລະ | J9: =J6-J8 -> 700000
A10: 46137 | B10: PO-003 | C10: ຄ່າແປງອຸປະກອນ | D10: Purchase | E10: 8000000 | F10: =IF(E10="","",ROUND(E10*Tax!$B$5,2)) -> 560000 | G10: =IF(E10="","",E10+F10) -> 8560000 | I10: ສະຖານະ | J10: =IF(J9>0,"ຕ້ອງຊຳລະພາສີ",IF(J9<0,"ມີເຄດິດພາສີຍົກໄປເດືອນຫນ້າ","ບໍ່ມີຍອດ")) -> ຕ້ອງຊຳລະພາສີ
F11: =IF(E11="","",ROUND(E11*Tax!$B$5,2)) | G11: =IF(E11="","",E11+F11)
F12: =IF(E12="","",ROUND(E12*Tax!$B$5,2)) | G12: =IF(E12="","",E12+F12)
F13: =IF(E13="","",ROUND(E13*Tax!$B$5,2)) | G13: =IF(E13="","",E13+F13)
F14: =IF(E14="","",ROUND(E14*Tax!$B$5,2)) | G14: =IF(E14="","",E14+F14)
F15: =IF(E15="","",ROUND(E15*Tax!$B$5,2)) | G15: =IF(E15="","",E15+F15)
F16: =IF(E16="","",ROUND(E16*Tax!$B$5,2)) | G16: =IF(E16="","",E16+F16)
F17: =IF(E17="","",ROUND(E17*Tax!$B$5,2)) | G17: =IF(E17="","",E17+F17)
F18: =IF(E18="","",ROUND(E18*Tax!$B$5,2)) | G18: =IF(E18="","",E18+F18)
F19: =IF(E19="","",ROUND(E19*Tax!$B$5,2)) | G19: =IF(E19="","",E19+F19)
F20: =IF(E20="","",ROUND(E20*Tax!$B$5,2)) | G20: =IF(E20="","",E20+F20)
F21: =IF(E21="","",ROUND(E21*Tax!$B$5,2)) | G21: =IF(E21="","",E21+F21)
F22: =IF(E22="","",ROUND(E22*Tax!$B$5,2)) | G22: =IF(E22="","",E22+F22)
... F104: =IF(E104="","",ROUND(E104*Tax!$B$5,2)) | G104: =IF(E104="","",E104+F104)

Sheet Category
A1: Category
A2: Sales
A3: Other Income
A4: Raw Material
A5: Wages
A6: Supplies
A7: Utilities
A8: Rent
A9: Weekly allowance
A10: Money
